data/sample_orders.csv
ts,action,id,side,type,price,qty
1,NEW,1,SELL,LIMIT,101,10
2,NEW,2,SELL,LIMIT,102,5
3,NEW,3,BUY,LIMIT,99,8
4,NEW,4,BUY,LIMIT,100,6
5,NEW,5,BUY,LIMIT,101,4
6,NEW,6,SELL,LIMIT,100,3
7,NEW,7,BUY,MARKET,0,5
8,CANCEL,2,,,,
9,NEW,8,SELL,LIMIT,103,7
10,NEW,9,BUY,IOC,103,20
